Workbook

Sheet README
A1: OZ 2.0 Candidate Tracts — Excel Export
A2: WFRC & MAG Region · Wasatch Front, Utah · Generated June 01, 2026
A4: ABOUT THIS WORKBOOK
A5: This workbook is a machine-generated backup of the WFRC/MAG Opportunity Zone 2.0 candidate tract analysis. It contains all metrics calculated in the R/GIS pipeline for every census tract on the federal OZ 2.0 eligible list within the nine-county Wasatch Front region. The Summary sheet mirrors the one-page PDF summary table. Per-county sheets mirror the detail PDF pages and include an embedded tract map. All values update automatically when the pipeline is re-run with new data.
A11: SHEETS IN THIS WORKBOOK
A12: Sheet Name | B12: Description
A13: README | B13: This sheet: methodology, column glossary, and abbreviation key.
A14: Summary | B14: All-tract summary table: one row per tract, 14 columns matching the PDF summary. Values cross-referenced from All Data.
A15: Box Elder County | B15: Box Elder County: per-tract detail blocks with embedded map images. Values cross-referenced from All Data.
A16: Weber County | B16: Weber County: per-tract detail blocks with embedded map images. Values cross-referenced from All Data.
A17: Davis County | B17: Davis County: per-tract detail blocks with embedded map images. Values cross-referenced from All Data.
A18: Salt Lake County | B18: Salt Lake County: per-tract detail blocks with embedded map images. Values cross-referenced from All Data.
A19: Tooele County | B19: Tooele County: per-tract detail blocks with embedded map images. Values cross-referenced from All Data.
A20: Utah County | B20: Utah County: per-tract detail blocks with embedded map images. Values cross-referenced from All Data.
A21: All Data | B21: Flat database: all 42 metrics for every tract in one filterable Excel Table. Derived columns use in-sheet formulas.
A23: ABBREVIATIONS & GLOSSARY
A24: Term | B24: Full Name | C24: Description
A25: ATO | B25: Access to Opportunities | C25: Composite 0-100 index combining driving and transit access to jobs and households.
A26: ERU | B26: Equivalent Residential Unit | C26: Growth density metric: 1 household = 1 ERU, 1 job = 0.4 ERU.
A27: SAP | B27: Station Area Plan | C27: Adopted housing plan within 1/2-mile of a rail or BRT stop.
A28: WC / MUorC | B28: Wasatch Choice / Metro-Urban-City Center | C28: WFRC/MAG regional growth center framework. MUorC = Metropolitan, Urban, or City center types.
A29: OZ 1.0 | B29: Opportunity Zones (2018 round) | C29: Prior federal OZ designations; overlap shown for context.
A30: OZ 2.0 | B30: Opportunity Zones 2.0 (current) | C30: Current federal eligible tract list under evaluation.
A31: TAZ | B31: Traffic Analysis Zone | C31: WFRC/MAG forecast unit; growth projections are area-proportioned from TAZ to tract.
A32: DEVACRES | B32: Developable Acres | C32: Developable land within a TAZ from the ATO layer; used as intersection weight for ATO scores.
A33: GEOID | B33: Census Tract Geographic ID | C33: 11-digit FIPS code: 2-digit state + 3-digit county + 6-digit tract.
A35: DATA SOURCES
A36: Federal OZ 2.0 Eligibility List — U.S. Treasury / HUD
A37: Urban Institute OZ Tool Classification — Urban Institute
A38: Wasatch Choice for 2050 Centers & Districts — WFRC/MAG
A39: ACS Population, Households, Income, Poverty, Unemployment — U.S. Census Bureau
A40: UTA Rail/BRT Stops — Utah Transit Authority
A41: Station Area Plans (SAP) — WFRC/MAG
A42: Freeway Interchanges — WFRC/MAG
A43: Housing Inventory — WFRC/MAG
A44: Access to Opportunities (ATO) Scores — WFRC/MAG
A45: TAZ Growth Projections 2027-2037 — WFRC/MAG

Sheet Summary
A1: OZ 2.0 Eligible Census Tracts — Wasatch Front Region | June 01, 2026
A2: # | B2: IDENTITY | E2: PROFILE | J2: FOUR KEY MEASURES | N2: INVESTMENT
A3: # | B3: County | C3: Tract | D3: GEOID | E3: Population | F3: Households | G3: Total Acres | H3: Dev Acres | I3: OZ 1.0 % | J3: WC MUorC % | K3: ATO /100 | L3: SAP HH/ac | M3: ERU/ac | N3: Investment Likelihood
A4: Box Elder County — 2 Eligible Tracts
A5: 01 | B5: Box Elder | C5: Tract 9606.01 | D5: 49003960601 | E5: ==IFERROR(INDEX('All Data'!$D:$D,MATCH($D5&"",'All Data'!$A:$A,0)),"-") | F5: ==IFERROR(INDEX('All Data'!$E:$E,MATCH($D5&"",'All Data'!$A:$A,0)),"-") | G5: ==IFERROR(INDEX('All Data'!$F:$F,MATCH($D5&"",'All Data'!$A:$A,0)),"-") | H5: ==IFERROR(INDEX('All Data'!$G:$G,MATCH($D5&"",'All Data'!$A:$A,0)),"-") | I5: ==IFERROR(INDEX('All Data'!$I:$I,MATCH($D5&"",'All Data'!$A:$A,0)),"-") | J5: ==IFERROR(INDEX('All Data'!$J:$J,MATCH($D5&"",'All Data'!$A:$A,0)),"-") | K5: ==IFERROR(INDEX('All Data'!$AF:$AF,MATCH($D5&"",'All Data'!$A:$A,0)),"-") | L5: ==IFERROR(INDEX('All Data'!$AA:$AA,MATCH($D5&"",'All Data'!$A:$A,0)),"-") | M5: ==IFERROR(INDEX('All Data'!$AK:$AK,MATCH($D5&"",'All Data'!$A:$A,0)),"-") | N5: ==IFERROR(INDEX('All Data'!$AP:$AP,MATCH($D5&"",'All Data'!$A:$A,0)),"-")
A6: 02 | B6: Box Elder | C6: Tract 9607.02 | D6: 49003960702 | E6: ==IFERROR(INDEX('All Data'!$D:$D,MATCH($D6&"",'All Data'!$A:$A,0)),"-") | F6: ==IFERROR(INDEX('All Data'!$E:$E,MATCH($D6&"",'All Data'!$A:$A,0)),"-") | G6: ==IFERROR(INDEX('All Data'!$F:$F,MATCH($D6&"",'All Data'!$A:$A,0)),"-") | H6: ==IFERROR(INDEX('All Data'!$G:$G,MATCH($D6&"",'All Data'!$A:$A,0)),"-") | I6: ==IFERROR(INDEX('All Data'!$I:$I,MATCH($D6&"",'All Data'!$A:$A,0)),"-") | J6: ==IFERROR(INDEX('All Data'!$J:$J,MATCH($D6&"",'All Data'!$A:$A,0)),"-") | K6: ==IFERROR(INDEX('All Data'!$AF:$AF,MATCH($D6&"",'All Data'!$A:$A,0)),"-") | L6: ==IFERROR(INDEX('All Data'!$AA:$AA,MATCH($D6&"",'All Data'!$A:$A,0)),"-") | M6: ==IFERROR(INDEX('All Data'!$AK:$AK,MATCH($D6&"",'All Data'!$A:$A,0)),"-") | N6: ==IFERROR(INDEX('All Data'!$AP:$AP,MATCH($D6&"",'All Data'!$A:$A,0)),"-")
A7: Weber County — 16 Eligible Tracts
A8: 01 | B8: Weber | C8: Tract 2002.02 | D8: 49057200202 | E8: ==IFERROR(INDEX('All Data'!$D:$D,MATCH($D8&"",'All Data'!$A:$A,0)),"-") | F8: ==IFERROR(INDEX('All Data'!$E:$E,MATCH($D8&"",'All Data'!$A:$A,0)),"-") | G8: ==IFERROR(INDEX('All Data'!$F:$F,MATCH($D8&"",'All Data'!$A:$A,0)),"-") | H8: ==IFERROR(INDEX('All Data'!$G:$G,MATCH($D8&"",'All Data'!$A:$A,0)),"-") | I8: ==IFERROR(INDEX('All Data'!$I:$I,MATCH($D8&"",'All Data'!$A:$A,0)),"-") | J8: ==IFERROR(INDEX('All Data'!$J:$J,MATCH($D8&"",'All Data'!$A:$A,0)),"-") | K8: ==IFERROR(INDEX('All Data'!$AF:$AF,MATCH($D8&"",'All Data'!$A:$A,0)),"-") | L8: ==IFERROR(INDEX('All Data'!$AA:$AA,MATCH($D8&"",'All Data'!$A:$A,0)),"-") | M8: ==IFERROR(INDEX('All Data'!$AK:$AK,MATCH($D8&"",'All Data'!$A:$A,0)),"-") | N8: ==IFERROR(INDEX('All Data'!$AP:$AP,MATCH($D8&"",'All Data'!$A:$A,0)),"-")
A9: 02 | B9: Weber | C9: Tract 2003.02 | D9: 49057200302 | E9: ==IFERROR(INDEX('All Data'!$D:$D,MATCH($D9&"",'All Data'!$A:$A,0)),"-") | F9: ==IFERROR(INDEX('All Data'!$E:$E,MATCH($D9&"",'All Data'!$A:$A,0)),"-") | G9: ==IFERROR(INDEX('All Data'!$F:$F,MATCH($D9&"",'All Data'!$A:$A,0)),"-") | H9: ==IFERROR(INDEX('All Data'!$G:$G,MATCH($D9&"",'All Data'!$A:$A,0)),"-") | I9: ==IFERROR(INDEX('All Data'!$I:$I,MATCH($D9&"",'All Data'!$A:$A,0)),"-") | J9: ==IFERROR(INDEX('All Data'!$J:$J,MATCH($D9&"",'All Data'!$A:$A,0)),"-") | K9: ==IFERROR(INDEX('All Data'!$AF:$AF,MATCH($D9&"",'All Data'!$A:$A,0)),"-") | L9: ==IFERROR(INDEX('All Data'!$AA:$AA,MATCH($D9&"",'All Data'!$A:$A,0)),"-") | M9: ==IFERROR(INDEX('All Data'!$AK:$AK,MATCH($D9&"",'All Data'!$A:$A,0)),"-") | N9: ==IFERROR(INDEX('All Data'!$AP:$AP,MATCH($D9&"",'All Data'!$A:$A,0)),"-")
A10: 03 | B10: Weber | C10: Tract 2004 | D10: 49057200400 | E10: ==IFERROR(INDEX('All Data'!$D:$D,MATCH($D10&"",'All Data'!$A:$A,0)),"-") | F10: ==IFERROR(INDEX('All Data'!$E:$E,MATCH($D10&"",'All Data'!$A:$A,0)),"-") | G10: ==IFERROR(INDEX('All Data'!$F:$F,MATCH($D10&"",'All Data'!$A:$A,0)),"-") | H10: ==IFERROR(INDEX('All Data'!$G:$G,MATCH($D10&"",'All Data'!$A:$A,0)),"-") | I10: ==IFERROR(INDEX('All Data'!$I:$I,MATCH($D10&"",'All Data'!$A:$A,0)),"-") | J10: ==IFERROR(INDEX('All Data'!$J:$J,MATCH($D10&"",'All Data'!$A:$A,0)),"-") | K10: ==IFERROR(INDEX('All Data'!$AF:$AF,MATCH($D10&"",'All Data'!$A:$A,0)),"-") | L10: ==IFERROR(INDEX('All Data'!$AA:$AA,MATCH($D10&"",'All Data'!$A:$A,0)),"-") | M10: ==IFERROR(INDEX('All Data'!$AK:$AK,MATCH($D10&"",'All Data'!$A:$A,0)),"-") | N10: ==IFERROR(INDEX('All Data'!$AP:$AP,MATCH($D10&"",'All Data'!$A:$A,0)),"-")
A11: 04 | B11: Weber | C11: Tract 2005 | D11: 49057200500 | E11: ==IFERROR(INDEX('All Data'!$D:$D,MATCH($D11&"",'All Data'!$A:$A,0)),"-") | F11: ==IFERROR(INDEX('All Data'!$E:$E,MATCH($D11&"",'All Data'!$A:$A,0)),"-") | G11: ==IFERROR(INDEX('All Data'!$F:$F,MATCH($D11&"",'All Data'!$A:$A,0)),"-") | H11: ==IFERROR(INDEX('All Data'!$G:$G,MATCH($D11&"",'All Data'!$A:$A,0)),"-") | I11: ==IFERROR(INDEX('All Data'!$I:$I,MATCH($D11&"",'All Data'!$A:$A,0)),"-") | J11: ==IFERROR(INDEX('All Data'!$J:$J,MATCH($D11&"",'All Data'!$A:$A,0)),"-") | K11: ==IFERROR(INDEX('All Data'!$AF:$AF,MATCH($D11&"",'All Data'!$A:$A,0)),"-") | L11: ==IFERROR(INDEX('All Data'!$AA:$AA,MATCH($D11&"",'All Data'!$A:$A,0)),"-") | M11: ==IFERROR(INDEX('All Data'!$AK:$AK,MATCH($D11&"",'All Data'!$A:$A,0)),"-") | N11: ==IFERROR(INDEX('All Data'!$AP:$AP,MATCH($D11&"",'All Data'!$A:$A,0)),"-")
A12: 05 | B12: Weber | C12: Tract 2008 | D12: 49057200800 | E12: ==IFERROR(INDEX('All Data'!$D:$D,MATCH($D12&"",'All Data'!$A:$A,0)),"-") | F12: ==IFERROR(INDEX('All Data'!$E:$E,MATCH($D12&"",'All Data'!$A:$A,0)),"-") | G12: ==IFERROR(INDEX('All Data'!$F:$F,MATCH($D12&"",'All Data'!$A:$A,0)),"-") | H12: ==IFERROR(INDEX('All Data'!$G:$G,MATCH($D12&"",'All Data'!$A:$A,0)),"-") | I12: ==IFERROR(INDEX('All Data'!$I:$I,MATCH($D12&"",'All Data'!$A:$A,0)),"-") | J12: ==IFERROR(INDEX('All Data'!$J:$J,MATCH($D12&"",'All Data'!$A:$A,0)),"-") | K12: ==IFERROR(INDEX('All Data'!$AF:$AF,MATCH($D12&"",'All Data'!$A:$A,0)),"-") | L12: ==IFERROR(INDEX('All Data'!$AA:$AA,MATCH($D12&"",'All Data'!$A:$A,0)),"-") | M12: ==IFERROR(INDEX('All Data'!$AK:$AK,MATCH($D12&"",'All Data'!$A:$A,0)),"-") | N12: ==IFERROR(INDEX('All Data'!$AP:$AP,MATCH($D12&"",'All Data'!$A:$A,0)),"-")
A13: 06 | B13: Weber | C13: Tract 2009 | D13: 49057200900 | E13: ==IFERROR(INDEX('All Data'!$D:$D,MATCH($D13&"",'All Data'!$A:$A,0)),"-") | F13: ==IFERROR(INDEX('All Data'!$E:$E,MATCH($D13&"",'All Data'!$A:$A,0)),"-") | G13: ==IFERROR(INDEX('All Data'!$F:$F,MATCH($D13&"",'All Data'!$A:$A,0)),"-") | H13: ==IFERROR(INDEX('All Data'!$G:$G,MATCH($D13&"",'All Data'!$A:$A,0)),"-") | I13: ==IFERROR(INDEX('All Data'!$I:$I,MATCH($D13&"",'All Data'!$A:$A,0)),"-") | J13: ==IFERROR(INDEX('All Data'!$J:$J,MATCH($D13&"",'All Data'!$A:$A,0)),"-") | K13: ==IFERROR(INDEX('All Data'!$AF:$AF,MATCH($D13&"",'All Data'!$A:$A,0)),"-") | L13: ==IFERROR(INDEX('All Data'!$AA:$AA,MATCH($D13&"",'All Data'!$A:$A,0)),"-") | M13: ==IFERROR(INDEX('All Data'!$AK:$AK,MATCH($D13&"",'All Data'!$A:$A,0)),"-") | N13: ==IFERROR(INDEX('All Data'!$AP:$AP,MATCH($D13&"",'All Data'!$A:$A,0)),"-")
A14: 07 | B14: Weber | C14: Tract 2011 | D14: 49057201100 | E14: ==IFERROR(INDEX('All Data'!$D:$D,MATCH($D14&"",'All Data'!$A:$A,0)),"-") | F14: ==IFERROR(INDEX('All Data'!$E:$E,MATCH($D14&"",'All Data'!$A:$A,0)),"-") | G14: ==IFERROR(INDEX('All Data'!$F:$F,MATCH($D14&"",'All Data'!$A:$A,0)),"-") | H14: ==IFERROR(INDEX('All Data'!$G:$G,MATCH($D14&"",'All Data'!$A:$A,0)),"-") | I14: ==IFERROR(INDEX('All Data'!$I:$I,MATCH($D14&"",'All Data'!$A:$A,0)),"-") | J14: ==IFERROR(INDEX('All Data'!$J:$J,MATCH($D14&"",'All Data'!$A:$A,0)),"-") | K14: ==IFERROR(INDEX('All Data'!$AF:$AF,MATCH($D14&"",'All Data'!$A:$A,0)),"-") | L14: ==IFERROR(INDEX('All Data'!$AA:$AA,MATCH($D14&"",'All Data'!$A:$A,0)),"-") | M14: ==IFERROR(INDEX('All Data'!$AK:$AK,MATCH($D14&"",'All Data'!$A:$A,0)),"-") | N14: ==IFERROR(INDEX('All Data'!$AP:$AP,MATCH($D14&"",'All Data'!$A:$A,0)),"-")
A15: 08 | B15: Weber | C15: Tract 2012 | D15: 49057201200 | E15: ==IFERROR(INDEX('All Data'!$D:$D,MATCH($D15&"",'All Data'!$A:$A,0)),"-") | F15: ==IFERROR(INDEX('All Data'!$E:$E,MATCH($D15&"",'All Data'!$A:$A,0)),"-") | G15: ==IFERROR(INDEX('All Data'!$F:$F,MATCH($D15&"",'All Data'!$A:$A,0)),"-") | H15: ==IFERROR(INDEX('All Data'!$G:$G,MATCH($D15&"",'All Data'!$A:$A,0)),"-") | I15: ==IFERROR(INDEX('All Data'!$I:$I,MATCH($D15&"",'All Data'!$A:$A,0)),"-") | J15: ==IFERROR(INDEX('All Data'!$J:$J,MATCH($D15&"",'All Data'!$A:$A,0)),"-") | K15: ==IFERROR(INDEX('All Data'!$AF:$AF,MATCH($D15&"",'All Data'!$A:$A,0)),"-") | L15: ==IFERROR(INDEX('All Data'!$AA:$AA,MATCH($D15&"",'All Data'!$A:$A,0)),"-") | M15: ==IFERROR(INDEX('All Data'!$AK:$AK,MATCH($D15&"",'All Data'!$A:$A,0)),"-") | N15: ==IFERROR(INDEX('All Data'!$AP:$AP,MATCH($D15&"",'All Data'!$A:$A,0)),"-")
A16: 09 | B16: Weber | C16: Tract 2013.01 | D16: 49057201301 | E16: ==IFERROR(INDEX('All Data'!$D:$D,MATCH($D16&"",'All Data'!$A:$A,0)),"-") | F16: ==IFERROR(INDEX('All Data'!$E:$E,MATCH($D16&"",'All Data'!$A:$A,0)),"-") | G16: ==IFERROR(INDEX('All Data'!$F:$F,MATCH($D16&"",'All Data'!$A:$A,0)),"-") | H16: ==IFERROR(INDEX('All Data'!$G:$G,MATCH($D16&"",'All Data'!$A:$A,0)),"-") | I16: ==IFERROR(INDEX('All Data'!$I:$I,MATCH($D16&"",'All Data'!$A:$A,0)),"-") | J16: ==IFERROR(INDEX('All Data'!$J:$J,MATCH($D16&"",'All Data'!$A:$A,0)),"-") | K16: ==IFERROR(INDEX('All Data'!$AF:$AF,MATCH($D16&"",'All Data'!$A:$A,0)),"-") | L16: ==IFERROR(INDEX('All Data'!$AA:$AA,MATCH($D16&"",'All Data'!$A:$A,0)),"-") | M16: ==IFERROR(INDEX('All Data'!$AK:$AK,MATCH($D16&"",'All Data'!$A:$A,0)),"-") | N16: ==IFERROR(INDEX('All Data'!$AP:$AP,MATCH($D16&"",'All Data'!$A:$A,0)),"-")
A17: 10 | B17: Weber | C17: Tract 2013.02 | D17: 49057201302 | E17: ==IFERROR(INDEX('All Data'!$D:$D,MATCH($D17&"",'All Data'!$A:$A,0)),"-") | F17: ==IFERROR(INDEX('All Data'!$E:$E,MATCH($D17&"",'All Data'!$A:$A,0)),"-") | G17: ==IFERROR(INDEX('All Data'!$F:$F,MATCH($D17&"",'All Data'!$A:$A,0)),"-") | H17: ==IFERROR(INDEX('All Data'!$G:$G,MATCH($D17&"",'All Data'!$A:$A,0)),"-") | I17: ==IFERROR(INDEX('All Data'!$I:$I,MATCH($D17&"",'All Data'!$A:$A,0)),"-") | J17: ==IFERROR(INDEX('All Data'!$J:$J,MATCH($D17&"",'All Data'!$A:$A,0)),"-") | K17: ==IFERROR(INDEX('All Data'!$AF:$AF,MATCH($D17&"",'All Data'!$A:$A,0)),"-") | L17: ==IFERROR(INDEX('All Data'!$AA:$AA,MATCH($D17&"",'All Data'!$A:$A,0)),"-") | M17: ==IFERROR(INDEX('All Data'!$AK:$AK,MATCH($D17&"",'All Data'!$A:$A,0)),"-") | N17: ==IFERROR(INDEX('All Data'!$AP:$AP,MATCH($D17&"",'All Data'!$A:$A,0)),"-")
A18: 11 | B18: Weber | C18: Tract 2016 | D18: 49057201600 | E18: ==IFERROR(INDEX('All Data'!$D:$D,MATCH($D18&"",'All Data'!$A:$A,0)),"-") | F18: ==IFERROR(INDEX('All Data'!$E:$E,MATCH($D18&"",'All Data'!$A:$A,0)),"-") | G18: ==IFERROR(INDEX('All Data'!$F:$F,MATCH($D18&"",'All Data'!$A:$A,0)),"-") | H18: ==IFERROR(INDEX('All Data'!$G:$G,MATCH($D18&"",'All Data'!$A:$A,0)),"-") | I18: ==IFERROR(INDEX('All Data'!$I:$I,MATCH($D18&"",'All Data'!$A:$A,0)),"-") | J18: ==IFERROR(INDEX('All Data'!$J:$J,MATCH($D18&"",'All Data'!$A:$A,0)),"-") | K18: ==IFERROR(INDEX('All Data'!$AF:$AF,MATCH($D18&"",'All Data'!$A:$A,0)),"-") | L18: ==IFERROR(INDEX('All Data'!$AA:$AA,MATCH($D18&"",'All Data'!$A:$A,0)),"-") | M18: ==IFERROR(INDEX('All Data'!$AK:$AK,MATCH($D18&"",'All Data'!$A:$A,0)),"-") | N18: ==IFERROR(INDEX('All Data'!$AP:$AP,MATCH($D18&"",'All Data'!$A:$A,0)),"-")
A19: 12 | B19: Weber | C19: Tract 2018 | D19: 49057201800 | E19: ==IFERROR(INDEX('All Data'!$D:$D,MATCH($D19&"",'All Data'!$A:$A,0)),"-") | F19: ==IFERROR(INDEX('All Data'!$E:$E,MATCH($D19&"",'All Data'!$A:$A,0)),"-") | G19: ==IFERROR(INDEX('All Data'!$F:$F,MATCH($D19&"",'All Data'!$A:$A,0)),"-") | H19: ==IFERROR(INDEX('All Data'!$G:$G,MATCH($D19&"",'All Data'!$A:$A,0)),"-") | I19: ==IFERROR(INDEX('All Data'!$I:$I,MATCH($D19&"",'All Data'!$A:$A,0)),"-") | J19: ==IFERROR(INDEX('All Data'!$J:$J,MATCH($D19&"",'All Data'!$A:$A,0)),"-") | K19: ==IFERROR(INDEX('All Data'!$AF:$AF,MATCH($D19&"",'All Data'!$A:$A,0)),"-") | L19: ==IFERROR(INDEX('All Data'!$AA:$AA,MATCH($D19&"",'All Data'!$A:$A,0)),"-") | M19: ==IFERROR(INDEX('All Data'!$AK:$AK,MATCH($D19&"",'All Data'!$A:$A,0)),"-") | N19: ==IFERROR(INDEX('All Data'!$AP:$AP,MATCH($D19&"",'All Data'!$A:$A,0)),"-")
... A23: 16 | B23: Weber | C23: Tract 2108 | D23: 49057210800 | E23: ==IFERROR(INDEX('All Data'!$D:$D,MATCH($D23&"",'All Data'!$A:$A,0)),"-") | F23: ==IFERROR(INDEX('All Data'!$E:$E,MATCH($D23&"",'All Data'!$A:$A,0)),"-") | G23: ==IFERROR(INDEX('All Data'!$F:$F,MATCH($D23&"",'All Data'!$A:$A,0)),"-") | H23: ==IFERROR(INDEX('All Data'!$G:$G,MATCH($D23&"",'All Data'!$A:$A,0)),"-") | I23: ==IFERROR(INDEX('All Data'!$I:$I,MATCH($D23&"",'All Data'!$A:$A,0)),"-") | J23: ==IFERROR(INDEX('All Data'!$J:$J,MATCH($D23&"",'All Data'!$A:$A,0)),"-") | K23: ==IFERROR(INDEX('All Data'!$AF:$AF,MATCH($D23&"",'All Data'!$A:$A,0)),"-") | L23: ==IFERROR(INDEX('All Data'!$AA:$AA,MATCH($D23&"",'All Data'!$A:$A,0)),"-") | M23: ==IFERROR(INDEX('All Data'!$AK:$AK,MATCH($D23&"",'All Data'!$A:$A,0)),"-") | N23: ==IFERROR(INDEX('All Data'!$AP:$AP,MATCH($D23&"",'All Data'!$A:$A,0)),"-")
A24: Davis County — 8 Eligible Tracts
A25: 01 | B25: Davis | C25: Tract 1252.01 | D25: 49011125201 | E25: ==IFERROR(INDEX('All Data'!$D:$D,MATCH($D25&"",'All Data'!$A:$A,0)),"-") | F25: ==IFERROR(INDEX('All Data'!$E:$E,MATCH($D25&"",'All Data'!$A:$A,0)),"-") | G25: ==IFERROR(INDEX('All Data'!$F:$F,MATCH($D25&"",'All Data'!$A:$A,0)),"-") | H25: ==IFERROR(INDEX('All Data'!$G:$G,MATCH($D25&"",'All Data'!$A:$A,0)),"-") | I25: ==IFERROR(INDEX('All Data'!$I:$I,MATCH($D25&"",'All Data'!$A:$A,0)),"-") | J25: ==IFERROR(INDEX('All Data'!$J:$J,MATCH($D25&"",'All Data'!$A:$A,0)),"-") | K25: ==IFERROR(INDEX('All Data'!$AF:$AF,MATCH($D25&"",'All Data'!$A:$A,0)),"-") | L25: ==IFERROR(INDEX('All Data'!$AA:$AA,MATCH($D25&"",'All Data'!$A:$A,0)),"-") | M25: ==IFERROR(INDEX('All Data'!$AK:$AK,MATCH($D25&"",'All Data'!$A:$A,0)),"-") | N25: ==IFERROR(INDEX('All Data'!$AP:$AP,MATCH($D25&"",'All Data'!$A:$A,0)),"-")
A26: 02 | B26: Davis | C26: Tract 1253.01 | D26: 49011125301 | E26: ==IFERROR(INDEX('All Data'!$D:$D,MATCH($D26&"",'All Data'!$A:$A,0)),"-") | F26: ==IFERROR(INDEX('All Data'!$E:$E,MATCH($D26&"",'All Data'!$A:$A,0)),"-") | G26: ==IFERROR(INDEX('All Data'!$F:$F,MATCH($D26&"",'All Data'!$A:$A,0)),"-") | H26: ==IFERROR(INDEX('All Data'!$G:$G,MATCH($D26&"",'All Data'!$A:$A,0)),"-") | I26: ==IFERROR(INDEX('All Data'!$I:$I,MATCH($D26&"",'All Data'!$A:$A,0)),"-") | J26: ==IFERROR(INDEX('All Data'!$J:$J,MATCH($D26&"",'All Data'!$A:$A,0)),"-") | K26: ==IFERROR(INDEX('All Data'!$AF:$AF,MATCH($D26&"",'All Data'!$A:$A,0)),"-") | L26: ==IFERROR(INDEX('All Data'!$AA:$AA,MATCH($D26&"",'All Data'!$A:$A,0)),"-") | M26: ==IFERROR(INDEX('All Data'!$AK:$AK,MATCH($D26&"",'All Data'!$A:$A,0)),"-") | N26: ==IFERROR(INDEX('All Data'!$AP:$AP,MATCH($D26&"",'All Data'!$A:$A,0)),"-")
A27: 03 | B27: Davis | C27: Tract 1256 | D27: 49011125600 | E27: ==IFERROR(INDEX('All Data'!$D:$D,MATCH($D27&"",'All Data'!$A:$A,0)),"-") | F27: ==IFERROR(INDEX('All Data'!$E:$E,MATCH($D27&"",'All Data'!$A:$A,0)),"-") | G27: ==IFERROR(INDEX('All Data'!$F:$F,MATCH($D27&"",'All Data'!$A:$A,0)),"-") | H27: ==IFERROR(INDEX('All Data'!$G:$G,MATCH($D27&"",'All Data'!$A:$A,0)),"-") | I27: ==IFERROR(INDEX('All Data'!$I:$I,MATCH($D27&"",'All Data'!$A:$A,0)),"-") | J27: ==IFERROR(INDEX('All Data'!$J:$J,MATCH($D27&"",'All Data'!$A:$A,0)),"-") | K27: ==IFERROR(INDEX('All Data'!$AF:$AF,MATCH($D27&"",'All Data'!$A:$A,0)),"-") | L27: ==IFERROR(INDEX('All Data'!$AA:$AA,MATCH($D27&"",'All Data'!$A:$A,0)),"-") | M27: ==IFERROR(INDEX('All Data'!$AK:$AK,MATCH($D27&"",'All Data'!$A:$A,0)),"-") | N27: ==IFERROR(INDEX('All Data'!$AP:$AP,MATCH($D27&"",'All Data'!$A:$A,0)),"-")
A28: 04 | B28: Davis | C28: Tract 1257.01 | D28: 49011125701 | E28: ==IFERROR(INDEX('All Data'!$D:$D,MATCH($D28&"",'All Data'!$A:$A,0)),"-") | F28: ==IFERROR(INDEX('All Data'!$E:$E,MATCH($D28&"",'All Data'!$A:$A,0)),"-") | G28: ==IFERROR(INDEX('All Data'!$F:$F,MATCH($D28&"",'All Data'!$A:$A,0)),"-") | H28: ==IFERROR(INDEX('All Data'!$G:$G,MATCH($D28&"",'All Data'!$A:$A,0)),"-") | I28: ==IFERROR(INDEX('All Data'!$I:$I,MATCH($D28&"",'All Data'!$A:$A,0)),"-") | J28: ==IFERROR(INDEX('All Data'!$J:$J,MATCH($D28&"",'All Data'!$A:$A,0)),"-") | K28: ==IFERROR(INDEX('All Data'!$AF:$AF,MATCH($D28&"",'All Data'!$A:$A,0)),"-") | L28: ==IFERROR(INDEX('All Data'!$AA:$AA,MATCH($D28&"",'All Data'!$A:$A,0)),"-") | M28: ==IFERROR(INDEX('All Data'!$AK:$AK,MATCH($D28&"",'All Data'!$A:$A,0)),"-") | N28: ==IFERROR(INDEX('All Data'!$AP:$AP,MATCH($D28&"",'All Data'!$A:$A,0)),"-")
A29: 05 | B29: Davis | C29: Tract 1257.02 | D29: 49011125702 | E29: ==IFERROR(INDEX('All Data'!$D:$D,MATCH($D29&"",'All Data'!$A:$A,0)),"-") | F29: ==IFERROR(INDEX('All Data'!$E:$E,MATCH($D29&"",'All Data'!$A:$A,0)),"-") | G29: ==IFERROR(INDEX('All Data'!$F:$F,MATCH($D29&"",'All Data'!$A:$A,0)),"-") | H29: ==IFERROR(INDEX('All Data'!$G:$G,MATCH($D29&"",'All Data'!$A:$A,0)),"-") | I29: ==IFERROR(INDEX('All Data'!$I:$I,MATCH($D29&"",'All Data'!$A:$A,0)),"-") | J29: ==IFERROR(INDEX('All Data'!$J:$J,MATCH($D29&"",'All Data'!$A:$A,0)),"-") | K29: ==IFERROR(INDEX('All Data'!$AF:$AF,MATCH($D29&"",'All Data'!$A:$A,0)),"-") | L29: ==IFERROR(INDEX('All Data'!$AA:$AA,MATCH($D29&"",'All Data'!$A:$A,0)),"-") | M29: ==IFERROR(INDEX('All Data'!$AK:$AK,MATCH($D29&"",'All Data'!$A:$A,0)),"-") | N29: ==IFERROR(INDEX('All Data'!$AP:$AP,MATCH($D29&"",'All Data'!$A:$A,0)),"-")
A30: 06 | B30: Davis | C30: Tract 1258.01 | D30: 49011125801 | E30: ==IFERROR(INDEX('All Data'!$D:$D,MATCH($D30&"",'All Data'!$A:$A,0)),"-") | F30: ==IFERROR(INDEX('All Data'!$E:$E,MATCH($D30&"",'All Data'!$A:$A,0)),"-") | G30: ==IFERROR(INDEX('All Data'!$F:$F,MATCH($D30&"",'All Data'!$A:$A,0)),"-") | H30: ==IFERROR(INDEX('All Data'!$G:$G,MATCH($D30&"",'All Data'!$A:$A,0)),"-") | I30: ==IFERROR(INDEX('All Data'!$I:$I,MATCH($D30&"",'All Data'!$A:$A,0)),"-") | J30: ==IFERROR(INDEX('All Data'!$J:$J,MATCH($D30&"",'All Data'!$A:$A,0)),"-") | K30: ==IFERROR(INDEX('All Data'!$AF:$AF,MATCH($D30&"",'All Data'!$A:$A,0)),"-") | L30: ==IFERROR(INDEX('All Data'!$AA:$AA,MATCH($D30&"",'All Data'!$A:$A,0)),"-") | M30: ==IFERROR(INDEX('All Data'!$AK:$AK,MATCH($D30&"",'All Data'!$A:$A,0)),"-") | N30: ==IFERROR(INDEX('All Data'!$AP:$AP,MATCH($D30&"",'All Data'!$A:$A,0)),"-")
A31: 07 | B31: Davis | C31: Tract 1258.10 | D31: 49011125810 | E31: ==IFERROR(INDEX('All Data'!$D:$D,MATCH($D31&"",'All Data'!$A:$A,0)),"-") | F31: ==IFERROR(INDEX('All Data'!$E:$E,MATCH($D31&"",'All Data'!$A:$A,0)),"-") | G31: ==IFERROR(INDEX('All Data'!$F:$F,MATCH($D31&"",'All Data'!$A:$A,0)),"-") | H31: ==IFERROR(INDEX('All Data'!$G:$G,MATCH($D31&"",'All Data'!$A:$A,0)),"-") | I31: ==IFERROR(INDEX('All Data'!$I:$I,MATCH($D31&"",'All Data'!$A:$A,0)),"-") | J31: ==IFERROR(INDEX('All Data'!$J:$J,MATCH($D31&"",'All Data'!$A:$A,0)),"-") | K31: ==IFERROR(INDEX('All Data'!$AF:$AF,MATCH($D31&"",'All Data'!$A:$A,0)),"-") | L31: ==IFERROR(INDEX('All Data'!$AA:$AA,MATCH($D31&"",'All Data'!$A:$A,0)),"-") | M31: ==IFERROR(INDEX('All Data'!$AK:$AK,MATCH($D31&"",'All Data'!$A:$A,0)),"-") | N31: ==IFERROR(INDEX('All Data'!$AP:$AP,MATCH($D31&"",'All Data'!$A:$A,0)),"-")
A32: 08 | B32: Davis | C32: Tract 1267 | D32: 49011126700 | E32: ==IFERROR(INDEX('All Data'!$D:$D,MATCH($D32&"",'All Data'!$A:$A,0)),"-") | F32: ==IFERROR(INDEX('All Data'!$E:$E,MATCH($D32&"",'All Data'!$A:$A,0)),"-") | G32: ==IFERROR(INDEX('All Data'!$F:$F,MATCH($D32&"",'All Data'!$A:$A,0)),"-") | H32: ==IFERROR(INDEX('All Data'!$G:$G,MATCH($D32&"",'All Data'!$A:$A,0)),"-") | I32: ==IFERROR(INDEX('All Data'!$I:$I,MATCH($D32&"",'All Data'!$A:$A,0)),"-") | J32: ==IFERROR(INDEX('All Data'!$J:$J,MATCH($D32&"",'All Data'!$A:$A,0)),"-") | K32: ==IFERROR(INDEX('All Data'!$AF:$AF,MATCH($D32&"",'All Data'!$A:$A,0)),"-") | L32: ==IFERROR(INDEX('All Data'!$AA:$AA,MATCH($D32&"",'All Data'!$A:$A,0)),"-") | M32: ==IFERROR(INDEX('All Data'!$AK:$AK,MATCH($D32&"",'All Data'!$A:$A,0)),"-") | N32: ==IFERROR(INDEX('All Data'!$AP:$AP,MATCH($D32&"",'All Data'!$A:$A,0)),"-")
A33: Salt Lake County — 49 Eligible Tracts
A34: 01 | B34: Salt Lake | C34: Tract 1003.06 | D34: 49035100306 | E34: ==IFERROR(INDEX('All Data'!$D:$D,MATCH($D34&"",'All Data'!$A:$A,0)),"-") | F34: ==IFERROR(INDEX('All Data'!$E:$E,MATCH($D34&"",'All Data'!$A:$A,0)),"-") | G34: ==IFERROR(INDEX('All Data'!$F:$F,MATCH($D34&"",'All Data'!$A:$A,0)),"-") | H34: ==IFERROR(INDEX('All Data'!$G:$G,MATCH($D34&"",'All Data'!$A:$A,0)),"-") | I34: ==IFERROR(INDEX('All Data'!$I:$I,MATCH($D34&"",'All Data'!$A:$A,0)),"-") | J34: ==IFERROR(INDEX('All Data'!$J:$J,MATCH($D34&"",'All Data'!$A:$A,0)),"-") | K34: ==IFERROR(INDEX('All Data'!$AF:$AF,MATCH($D34&"",'All Data'!$A:$A,0)),"-") | L34: ==IFERROR(INDEX('All Data'!$AA:$AA,MATCH($D34&"",'All Data'!$A:$A,0)),"-") | M34: ==IFERROR(INDEX('All Data'!$AK:$AK,MATCH($D34&"",'All Data'!$A:$A,0)),"-") | N34: ==IFERROR(INDEX('All Data'!$AP:$AP,MATCH($D34&"",'All Data'!$A:$A,0)),"-")
A35: 02 | B35: Salt Lake | C35: Tract 1003.08 | D35: 49035100308 | E35: ==IFERROR(INDEX('All Data'!$D:$D,MATCH($D35&"",'All Data'!$A:$A,0)),"-") | F35: ==IFERROR(INDEX('All Data'!$E:$E,MATCH($D35&"",'All Data'!$A:$A,0)),"-") | G35: ==IFERROR(INDEX('All Data'!$F:$F,MATCH($D35&"",'All Data'!$A:$A,0)),"-") | H35: ==IFERROR(INDEX('All Data'!$G:$G,MATCH($D35&"",'All Data'!$A:$A,0)),"-") | I35: ==IFERROR(INDEX('All Data'!$I:$I,MATCH($D35&"",'All Data'!$A:$A,0)),"-") | J35: ==IFERROR(INDEX('All Data'!$J:$J,MATCH($D35&"",'All Data'!$A:$A,0)),"-") | K35: ==IFERROR(INDEX('All Data'!$AF:$AF,MATCH($D35&"",'All Data'!$A:$A,0)),"-") | L35: ==IFERROR(INDEX('All Data'!$AA:$AA,MATCH($D35&"",'All Data'!$A:$A,0)),"-") | M35: ==IFERROR(INDEX('All Data'!$AK:$AK,MATCH($D35&"",'All Data'!$A:$A,0)),"-") | N35: ==IFERROR(INDEX('All Data'!$AP:$AP,MATCH($D35&"",'All Data'!$A:$A,0)),"-")
A36: 03 | B36: Salt Lake | C36: Tract 1005 | D36: 49035100500 | E36: ==IFERROR(INDEX('All Data'!$D:$D,MATCH($D36&"",'All Data'!$A:$A,0)),"-") | F36: ==IFERROR(INDEX('All Data'!$E:$E,MATCH($D36&"",'All Data'!$A:$A,0)),"-") | G36: ==IFERROR(INDEX('All Data'!$F:$F,MATCH($D36&"",'All Data'!$A:$A,0)),"-") | H36: ==IFERROR(INDEX('All Data'!$G:$G,MATCH($D36&"",'All Data'!$A:$A,0)),"-") | I36: ==IFERROR(INDEX('All Data'!$I:$I,MATCH($D36&"",'All Data'!$A:$A,0)),"-") | J36: ==IFERROR(INDEX('All Data'!$J:$J,MATCH($D36&"",'All Data'!$A:$A,0)),"-") | K36: ==IFERROR(INDEX('All Data'!$AF:$AF,MATCH($D36&"",'All Data'!$A:$A,0)),"-") | L36: ==IFERROR(INDEX('All Data'!$AA:$AA,MATCH($D36&"",'All Data'!$A:$A,0)),"-") | M36: ==IFERROR(INDEX('All Data'!$AK:$AK,MATCH($D36&"",'All Data'!$A:$A,0)),"-") | N36: ==IFERROR(INDEX('All Data'!$AP:$AP,MATCH($D36&"",'All Data'!$A:$A,0)),"-")
A37: 04 | B37: Salt Lake | C37: Tract 1006 | D37: 49035100600 | E37: ==IFERROR(INDEX('All Data'!$D:$D,MATCH($D37&"",'All Data'!$A:$A,0)),"-") | F37: ==IFERROR(INDEX('All Data'!$E:$E,MATCH($D37&"",'All Data'!$A:$A,0)),"-") | G37: ==IFERROR(INDEX('All Data'!$F:$F,MATCH($D37&"",'All Data'!$A:$A,0)),"-") | H37: ==IFERROR(INDEX('All Data'!$G:$G,MATCH($D37&"",'All Data'!$A:$A,0)),"-") | I37: ==IFERROR(INDEX('All Data'!$I:$I,MATCH($D37&"",'All Data'!$A:$A,0)),"-") | J37: ==IFERROR(INDEX('All Data'!$J:$J,MATCH($D37&"",'All Data'!$A:$A,0)),"-") | K37: ==IFERROR(INDEX('All Data'!$AF:$AF,MATCH($D37&"",'All Data'!$A:$A,0)),"-") | L37: ==IFERROR(INDEX('All Data'!$AA:$AA,MATCH($D37&"",'All Data'!$A:$A,0)),"-") | M37: ==IFERROR(INDEX('All Data'!$AK:$AK,MATCH($D37&"",'All Data'!$A:$A,0)),"-") | N37: ==IFERROR(INDEX('All Data'!$AP:$AP,MATCH($D37&"",'All Data'!$A:$A,0)),"-")
A38: 05 | B38: Salt Lake | C38: Tract 1008 | D38: 49035100800 | E38: ==IFERROR(INDEX('All Data'!$D:$D,MATCH($D38&"",'All Data'!$A:$A,0)),"-") | F38: ==IFERROR(INDEX('All Data'!$E:$E,MATCH($D38&"",'All Data'!$A:$A,0)),"-") | G38: ==IFERROR(INDEX('All Data'!$F:$F,MATCH($D38&"",'All Data'!$A:$A,0)),"-") | H38: ==IFERROR(INDEX('All Data'!$G:$G,MATCH($D38&"",'All Data'!$A:$A,0)),"-") | I38: ==IFERROR(INDEX('All Data'!$I:$I,MATCH($D38&"",'All Data'!$A:$A,0)),"-") | J38: ==IFERROR(INDEX('All Data'!$J:$J,MATCH($D38&"",'All Data'!$A:$A,0)),"-") | K38: ==IFERROR(INDEX('All Data'!$AF:$AF,MATCH($D38&"",'All Data'!$A:$A,0)),"-") | L38: ==IFERROR(INDEX('All Data'!$AA:$AA,MATCH($D38&"",'All Data'!$A:$A,0)),"-") | M38: ==IFERROR(INDEX('All Data'!$AK:$AK,MATCH($D38&"",'All Data'!$A:$A,0)),"-") | N38: ==IFERROR(INDEX('All Data'!$AP:$AP,MATCH($D38&"",'All Data'!$A:$A,0)),"-")
A39: 06 | B39: Salt Lake | C39: Tract 1014.01 | D39: 49035101401 | E39: ==IFERROR(INDEX('All Data'!$D:$D,MATCH($D39&"",'All Data'!$A:$A,0)),"-") | F39: ==IFERROR(INDEX('All Data'!$E:$E,MATCH($D39&"",'All Data'!$A:$A,0)),"-") | G39: ==IFERROR(INDEX('All Data'!$F:$F,MATCH($D39&"",'All Data'!$A:$A,0)),"-") | H39: ==IFERROR(INDEX('All Data'!$G:$G,MATCH($D39&"",'All Data'!$A:$A,0)),"-") | I39: ==IFERROR(INDEX('All Data'!$I:$I,MATCH($D39&"",'All Data'!$A:$A,0)),"-") | J39: ==IFERROR(INDEX('All Data'!$J:$J,MATCH($D39&"",'All Data'!$A:$A,0)),"-") | K39: ==IFERROR(INDEX('All Data'!$AF:$AF,MATCH($D39&"",'All Data'!$A:$A,0)),"-") | L39: ==IFERROR(INDEX('All Data'!$AA:$AA,MATCH($D39&"",'All Data'!$A:$A,0)),"-") | M39: ==IFERROR(INDEX('All Data'!$AK:$AK,MATCH($D39&"",'All Data'!$A:$A,0)),"-") | N39: ==IFERROR(INDEX('All Data'!$AP:$AP,MATCH($D39&"",'All Data'!$A:$A,0)),"-")
A40: 07 | B40: Salt Lake | C40: Tract 1014.02 | D40: 49035101402 | E40: ==IFERROR(INDEX('All Data'!$D:$D,MATCH($D40&"",'All Data'!$A:$A,0)),"-") | F40: ==IFERROR(INDEX('All Data'!$E:$E,MATCH($D40&"",'All Data'!$A:$A,0)),"-") | G40: ==IFERROR(INDEX('All Data'!$F:$F,MATCH($D40&"",'All Data'!$A:$A,0)),"-") | H40: ==IFERROR(INDEX('All Data'!$G:$G,MATCH($D40&"",'All Data'!$A:$A,0)),"-") | I40: ==IFERROR(INDEX('All Data'!$I:$I,MATCH($D40&"",'All Data'!$A:$A,0)),"-") | J40: ==IFERROR(INDEX('All Data'!$J:$J,MATCH($D40&"",'All Data'!$A:$A,0)),"-") | K40: ==IFERROR(INDEX('All Data'!$AF:$AF,MATCH($D40&"",'All Data'!$A:$A,0)),"-") | L40: ==IFERROR(INDEX('All Data'!$AA:$AA,MATCH($D40&"",'All Data'!$A:$A,0)),"-") | M40: ==IFERROR(INDEX('All Data'!$AK:$AK,MATCH($D40&"",'All Data'!$A:$A,0)),"-") | N40: ==IFERROR(INDEX('All Data'!$AP:$AP,MATCH($D40&"",'All Data'!$A:$A,0)),"-")
A41: 08 | B41: Salt Lake | C41: Tract 1015 | D41: 49035101500 | E41: ==IFERROR(INDEX('All Data'!$D:$D,MATCH($D41&"",'All Data'!$A:$A,0)),"-") | F41: ==IFERROR(INDEX('All Data'!$E:$E,MATCH($D41&"",'All Data'!$A:$A,0)),"-") | G41: ==IFERROR(INDEX('All Data'!$F:$F,MATCH($D41&"",'All Data'!$A:$A,0)),"-") | H41: ==IFERROR(INDEX('All Data'!$G:$G,MATCH($D41&"",'All Data'!$A:$A,0)),"-") | I41: ==IFERROR(INDEX('All Data'!$I:$I,MATCH($D41&"",'All Data'!$A:$A,0)),"-") | J41: ==IFERROR(INDEX('All Data'!$J:$J,MATCH($D41&"",'All Data'!$A:$A,0)),"-") | K41: ==IFERROR(INDEX('All Data'!$AF:$AF,MATCH($D41&"",'All Data'!$A:$A,0)),"-") | L41: ==IFERROR(INDEX('All Data'!$AA:$AA,MATCH($D41&"",'All Data'!$A:$A,0)),"-") | M41: ==IFERROR(INDEX('All Data'!$AK:$AK,MATCH($D41&"",'All Data'!$A:$A,0)),"-") | N41: ==IFERROR(INDEX('All Data'!$AP:$AP,MATCH($D41&"",'All Data'!$A:$A,0)),"-")
A42: 09 | B42: Salt Lake | C42: Tract 1016 | D42: 49035101600 | E42: ==IFERROR(INDEX('All Data'!$D:$D,MATCH($D42&"",'All Data'!$A:$A,0)),"-") | F42: ==IFERROR(INDEX('All Data'!$E:$E,MATCH($D42&"",'All Data'!$A:$A,0)),"-") | G42: ==IFERROR(INDEX('All Data'!$F:$F,MATCH($D42&"",'All Data'!$A:$A,0)),"-") | H42: ==IFERROR(INDEX('All Data'!$G:$G,MATCH($D42&"",'All Data'!$A:$A,0)),"-") | I42: ==IFERROR(INDEX('All Data'!$I:$I,MATCH($D42&"",'All Data'!$A:$A,0)),"-") | J42: ==IFERROR(INDEX('All Data'!$J:$J,MATCH($D42&"",'All Data'!$A:$A,0)),"-") | K42: ==IFERROR(INDEX('All Data'!$AF:$AF,MATCH($D42&"",'All Data'!$A:$A,0)),"-") | L42: ==IFERROR(INDEX('All Data'!$AA:$AA,MATCH($D42&"",'All Data'!$A:$A,0)),"-") | M42: ==IFERROR(INDEX('All Data'!$AK:$AK,MATCH($D42&"",'All Data'!$A:$A,0)),"-") | N42: ==IFERROR(INDEX('All Data'!$AP:$AP,MATCH($D42&"",'All Data'!$A:$A,0)),"-")
A43: 10 | B43: Salt Lake | C43: Tract 1017 | D43: 49035101700 | E43: ==IFERROR(INDEX('All Data'!$D:$D,MATCH($D43&"",'All Data'!$A:$A,0)),"-") | F43: ==IFERROR(INDEX('All Data'!$E:$E,MATCH($D43&"",'All Data'!$A:$A,0)),"-") | G43: ==IFERROR(INDEX('All Data'!$F:$F,MATCH($D43&"",'All Data'!$A:$A,0)),"-") | H43: ==IFERROR(INDEX('All Data'!$G:$G,MATCH($D43&"",'All Data'!$A:$A,0)),"-") | I43: ==IFERROR(INDEX('All Data'!$I:$I,MATCH($D43&"",'All Data'!$A:$A,0)),"-") | J43: ==IFERROR(INDEX('All Data'!$J:$J,MATCH($D43&"",'All Data'!$A:$A,0)),"-") | K43: ==IFERROR(INDEX('All Data'!$AF:$AF,MATCH($D43&"",'All Data'!$A:$A,0)),"-") | L43: ==IFERROR(INDEX('All Data'!$AA:$AA,MATCH($D43&"",'All Data'!$A:$A,0)),"-") | M43: ==IFERROR(INDEX('All Data'!$AK:$AK,MATCH($D43&"",'All Data'!$A:$A,0)),"-") | N43: ==IFERROR(INDEX('All Data'!$AP:$AP,MATCH($D43&"",'All Data'!$A:$A,0)),"-")
...

Sheet Box Elder County
A1: Box Elder County — OZ 2.0 Candidate Tracts — Detail
A2: WFRC & MAG Region | Generated June 01, 2026
A4: =="01 — "&IFERROR(INDEX('All Data'!$C:$C,MATCH($H$4&"",'All Data'!$A:$A,0)),"")&" | GEOID "&$H$4&" | "&TEXT(IFERROR(INDEX('All Data'!$F:$F,MATCH($H$4&"",'All Data'!$A:$A,0)),0),"0")&" ac | "&IFERROR(INDEX('All Data'!$AP:$AP,MATCH($H$4&"",'All Data'!$A:$A,0)),"—") | H4: 49003960601
B5: TRACT PROFILE | D5: CENTERS & DISTRICTS | F5: HOUSING & DEMOGRAPHICS
B6: Population | C6: ==IFERROR(INDEX('All Data'!$D:$D,MATCH($H$4&"",'All Data'!$A:$A,0)),"-") | D6: WC MUorC % Total | E6: ==IFERROR(INDEX('All Data'!$J:$J,MATCH($H$4&"",'All Data'!$A:$A,0)),"-") | F6: Total Units | G6: ==IFERROR(INDEX('All Data'!$R:$R,MATCH($H$4&"",'All Data'!$A:$A,0)),"-")
B7: Households | C7: ==IFERROR(INDEX('All Data'!$E:$E,MATCH($H$4&"",'All Data'!$A:$A,0)),"-") | D7: Metropolitan Center | E7: ==IFERROR(INDEX('All Data'!$K:$K,MATCH($H$4&"",'All Data'!$A:$A,0)),"-") | F7: Residential Acres | G7: ==IFERROR(INDEX('All Data'!$S:$S,MATCH($H$4&"",'All Data'!$A:$A,0)),"-")
B8: Total Acres | C8: ==IFERROR(INDEX('All Data'!$F:$F,MATCH($H$4&"",'All Data'!$A:$A,0)),"-") | D8: Urban Center | E8: ==IFERROR(INDEX('All Data'!$L:$L,MATCH($H$4&"",'All Data'!$A:$A,0)),"-") | F8: SFD Acres | G8: ==IFERROR(INDEX('All Data'!$T:$T,MATCH($H$4&"",'All Data'!$A:$A,0)),"-")
B9: Developable Acres | C9: ==IFERROR(INDEX('All Data'!$G:$G,MATCH($H$4&"",'All Data'!$A:$A,0)),"-") | D9: City Center | E9: ==IFERROR(INDEX('All Data'!$M:$M,MATCH($H$4&"",'All Data'!$A:$A,0)),"-") | F9: MF / SFA Acres | G9: ==IFERROR(INDEX('All Data'!$U:$U,MATCH($H$4&"",'All Data'!$A:$A,0)),"-")
B10: OZ 1.0 Acres | C10: ==IFERROR(INDEX('All Data'!$H:$H,MATCH($H$4&"",'All Data'!$A:$A,0)),"-") | D10: Neighborhood Center | E10: ==IFERROR(INDEX('All Data'!$N:$N,MATCH($H$4&"",'All Data'!$A:$A,0)),"-") | F10: Poverty Rate | G10: ==IFERROR(INDEX('All Data'!$AL:$AL,MATCH($H$4&"",'All Data'!$A:$A,0)),"-")
B11: OZ 1.0 % of Tract | C11: ==IFERROR(INDEX('All Data'!$I:$I,MATCH($H$4&"",'All Data'!$A:$A,0)),"-") | D11: Employment District | E11: ==IFERROR(INDEX('All Data'!$O:$O,MATCH($H$4&"",'All Data'!$A:$A,0)),"-") | F11: Unemployment Rate | G11: ==IFERROR(INDEX('All Data'!$AM:$AM,MATCH($H$4&"",'All Data'!$A:$A,0)),"-")
D12: Industrial District | E12: ==IFERROR(INDEX('All Data'!$P:$P,MATCH($H$4&"",'All Data'!$A:$A,0)),"-") | F12: Median Family Income | G12: ==IFERROR(INDEX('All Data'!$AN:$AN,MATCH($H$4&"",'All Data'!$A:$A,0)),"-")
D13: Retail District | E13: ==IFERROR(INDEX('All Data'!$Q:$Q,MATCH($H$4&"",'All Data'!$A:$A,0)),"-")
B14: TRANSIT ACCESS | D14: AUTO ACCESS | F14: PROJECTED GROWTH 2027-37
B15: Rail / BRT Stops | C15: ==IFERROR(INDEX('All Data'!$V:$V,MATCH($H$4&"",'All Data'!$A:$A,0)),"-") | D15: Freeway Exits | E15: ==IFERROR(INDEX('All Data'!$AB:$AB,MATCH($H$4&"",'All Data'!$A:$A,0)),"-") | F15: Households Added | G15: ==IFERROR(INDEX('All Data'!$AG:$AG,MATCH($H$4&"",'All Data'!$A:$A,0)),"-")
B16: SAP Acres | C16: ==IFERROR(INDEX('All Data'!$W:$W,MATCH($H$4&"",'All Data'!$A:$A,0)),"-") | D16: Exit Distance (mi) | E16: ==IFERROR(INDEX('All Data'!$AC:$AC,MATCH($H$4&"",'All Data'!$A:$A,0)),"-") | F16: Population Added | G16: ==IFERROR(INDEX('All Data'!$AH:$AH,MATCH($H$4&"",'All Data'!$A:$A,0)),"-")
B17: SAP % of Tract | C17: ==IFERROR(INDEX('All Data'!$X:$X,MATCH($H$4&"",'All Data'!$A:$A,0)),"-") | D17: ATO Jobs (Auto) | E17: ==IFERROR(INDEX('All Data'!$AD:$AD,MATCH($H$4&"",'All Data'!$A:$A,0)),"-") | F17: Jobs Added | G17: ==IFERROR(INDEX('All Data'!$AI:$AI,MATCH($H$4&"",'All Data'!$A:$A,0)),"-")
B18: ATO Jobs (Transit) | C18: ==IFERROR(INDEX('All Data'!$Y:$Y,MATCH($H$4&"",'All Data'!$A:$A,0)),"-") | D18: ATO Households (Auto) | E18: ==IFERROR(INDEX('All Data'!$AE:$AE,MATCH($H$4&"",'All Data'!$A:$A,0)),"-") | F18: ERU Added | G18: ==IFERROR(INDEX('All Data'!$AJ:$AJ,MATCH($H$4&"",'All Data'!$A:$A,0)),"-")
B19: ATO Households (Transit) | C19: ==IFERROR(INDEX('All Data'!$Z:$Z,MATCH($H$4&"",'All Data'!$A:$A,0)),"-") | F19: ERU per Acre | G19: ==IFERROR(INDEX('All Data'!$AK:$AK,MATCH($H$4&"",'All Data'!$A:$A,0)),"-")
B20: SAP Planned HH/ac | C20: ==IFERROR(INDEX('All Data'!$AA:$AA,MATCH($H$4&"",'All Data'!$A:$A,0)),"-")
B22: INCOME | D22: POVERTY RATE | F22: UNEMPLOYMENT
C23: ==IFERROR(INDEX('All Data'!$AN:$AN,MATCH($H$4&"",'All Data'!$A:$A,0)),"-") | E23: ==IFERROR(INDEX('All Data'!$AL:$AL,MATCH($H$4&"",'All Data'!$A:$A,0)),"-") | G23: ==IFERROR(INDEX('All Data'!$AM:$AM,MATCH($H$4&"",'All Data'!$A:$A,0)),"-")
B24: =="Investment Likelihood: "&IFERROR(INDEX('All Data'!$AP:$AP,MATCH($H$4&"",'All Data'!$A:$A,0)),"—")
B25: Access to Opportunities (ATO) Composite Score /100 | F25: ==IFERROR(INDEX('All Data'!$AF:$AF,MATCH($H$4&"",'All Data'!$A:$A,0)),"-")
A29: =="02 — "&IFERROR(INDEX('All Data'!$C:$C,MATCH($H$29&"",'All Data'!$A:$A,0)),"")&" | GEOID "&$H$29&" | "&TEXT(IFERROR(INDEX('All Data'!$F:$F,MATCH($H$29&"",'All Data'!$A:$A,0)),0),"0")&" ac | "&IFERROR(INDEX('All Data'!$AP:$AP,MATCH($H$29&"",'All Data'!$A:$A,0)),"—") | H29: 49003960702
B30: TRACT PROFILE | D30: CENTERS & DISTRICTS | F30: HOUSING & DEMOGRAPHICS
B31: Population | C31: ==IFERROR(INDEX('All Data'!$D:$D,MATCH($H$29&"",'All Data'!$A:$A,0)),"-") | D31: WC MUorC % Total | E31: ==IFERROR(INDEX('All Data'!$J:$J,MATCH($H$29&"",'All Data'!$A:$A,0)),"-") | F31: Total Units | G31: ==IFERROR(INDEX('All Data'!$R:$R,MATCH($H$29&"",'All Data'!$A:$A,0)),"-")
B32: Households | C32: ==IFERROR(INDEX('All Data'!$E:$E,MATCH($H$29&"",'All Data'!$A:$A,0)),"-") | D32: Metropolitan Center | E32: ==IFERROR(INDEX('All Data'!$K:$K,MATCH($H$29&"",'All Data'!$A:$A,0)),"-") | F32: Residential Acres | G32: ==IFERROR(INDEX('All Data'!$S:$S,MATCH($H$29&"",'All Data'!$A:$A,0)),"-")
B33: Total Acres | C33: ==IFERROR(INDEX('All Data'!$F:$F,MATCH($H$29&"",'All Data'!$A:$A,0)),"-") | D33: Urban Center | E33: ==IFERROR(INDEX('All Data'!$L:$L,MATCH($H$29&"",'All Data'!$A:$A,0)),"-") | F33: SFD Acres | G33: ==IFERROR(INDEX('All Data'!$T:$T,MATCH($H$29&"",'All Data'!$A:$A,0)),"-")
B34: Developable Acres | C34: ==IFERROR(INDEX('All Data'!$G:$G,MATCH($H$29&"",'All Data'!$A:$A,0)),"-") | D34: City Center | E34: ==IFERROR(INDEX('All Data'!$M:$M,MATCH($H$29&"",'All Data'!$A:$A,0)),"-") | F34: MF / SFA Acres | G34: ==IFERROR(INDEX('All Data'!$U:$U,MATCH($H$29&"",'All Data'!$A:$A,0)),"-")
B35: OZ 1.0 Acres | C35: ==IFERROR(INDEX('All Data'!$H:$H,MATCH($H$29&"",'All Data'!$A:$A,0)),"-") | D35: Neighborhood Center | E35: ==IFERROR(INDEX('All Data'!$N:$N,MATCH($H$29&"",'All Data'!$A:$A,0)),"-") | F35: Poverty Rate | G35: ==IFERROR(INDEX('All Data'!$AL:$AL,MATCH($H$29&"",'All Data'!$A:$A,0)),"-")
B36: OZ 1.0 % of Tract | C36: ==IFERROR(INDEX('All Data'!$I:$I,MATCH($H$29&"",'All Data'!$A:$A,0)),"-") | D36: Employment District | E36: ==IFERROR(INDEX('All Data'!$O:$O,MATCH($H$29&"",'All Data'!$A:$A,0)),"-") | F36: Unemployment Rate | G36: ==IFERROR(INDEX('All Data'!$AM:$AM,MATCH($H$29&"",'All Data'!$A:$A,0)),"-")
D37: Industrial District | E37: ==IFERROR(INDEX('All Data'!$P:$P,MATCH($H$29&"",'All Data'!$A:$A,0)),"-") | F37: Median Family Income | G37: ==IFERROR(INDEX('All Data'!$AN:$AN,MATCH($H$29&"",'All Data'!$A:$A,0)),"-")
D38: Retail District | E38: ==IFERROR(INDEX('All Data'!$Q:$Q,MATCH($H$29&"",'All Data'!$A:$A,0)),"-")
B39: TRANSIT ACCESS | D39: AUTO ACCESS | F39: PROJECTED GROWTH 2027-37
B40: Rail / BRT Stops | C40: ==IFERROR(INDEX('All Data'!$V:$V,MATCH($H$29&"",'All Data'!$A:$A,0)),"-") | D40: Freeway Exits | E40: ==IFERROR(INDEX('All Data'!$AB:$AB,MATCH($H$29&"",'All Data'!$A:$A,0)),"-") | F40: Households Added | G40: ==IFERROR(INDEX('All Data'!$AG:$AG,MATCH($H$29&"",'All Data'!$A:$A,0)),"-")
B41: SAP Acres | C41: ==IFERROR(INDEX('All Data'!$W:$W,MATCH($H$29&"",'All Data'!$A:$A,0)),"-") | D41: Exit Distance (mi) | E41: ==IFERROR(INDEX('All Data'!$AC:$AC,MATCH($H$29&"",'All Data'!$A:$A,0)),"-") | F41: Population Added | G41: ==IFERROR(INDEX('All Data'!$AH:$AH,MATCH($H$29&"",'All Data'!$A:$A,0)),"-")
B42: SAP % of Tract | C42: ==IFERROR(INDEX('All Data'!$X:$X,MATCH($H$29&"",'All Data'!$A:$A,0)),"-") | D42: ATO Jobs (Auto) | E42: ==IFERROR(INDEX('All Data'!$AD:$AD,MATCH($H$29&"",'All Data'!$A:$A,0)),"-") | F42: Jobs Added | G42: ==IFERROR(INDEX('All Data'!$AI:$AI,MATCH($H$29&"",'All Data'!$A:$A,0)),"-")
B43: ATO Jobs (Transit) | C43: ==IFERROR(INDEX('All Data'!$Y:$Y,MATCH($H$29&"",'All Data'!$A:$A,0)),"-") | D43: ATO Households (Auto) | E43: ==IFERROR(INDEX('All Data'!$AE:$AE,MATCH($H$29&"",'All Data'!$A:$A,0)),"-") | F43: ERU Added | G43: ==IFERROR(INDEX('All Data'!$AJ:$AJ,MATCH($H$29&"",'All Data'!$A:$A,0)),"-")
B44: ATO Households (Transit) | C44: ==IFERROR(INDEX('All Data'!$Z:$Z,MATCH($H$29&"",'All Data'!$A:$A,0)),"-") | F44: ERU per Acre | G44: ==IFERROR(INDEX('All Data'!$AK:$AK,MATCH($H$29&"",'All Data'!$A:$A,0)),"-")
B45: SAP Planned HH/ac | C45: ==IFERROR(INDEX('All Data'!$AA:$AA,MATCH($H$29&"",'All Data'!$A:$A,0)),"-")
...

Sheet Weber County
A1: Weber County — OZ 2.0 Candidate Tracts — Detail
A2: WFRC & MAG Region | Generated June 01, 2026
A4: =="01 — "&IFERROR(INDEX('All Data'!$C:$C,MATCH($H$4&"",'All Data'!$A:$A,0)),"")&" | GEOID "&$H$4&" | "&TEXT(IFERROR(INDEX('All Data'!$F:$F,MATCH($H$4&"",'All Data'!$A:$A,0)),0),"0")&" ac | "&IFERROR(INDEX('All Data'!$AP:$AP,MATCH($H$4&"",'All Data'!$A:$A,0)),"—") | H4: 49057200202
B5: TRACT PROFILE | D5: CENTERS & DISTRICTS | F5: HOUSING & DEMOGRAPHICS
B6: Population | C6: ==IFERROR(INDEX('All Data'!$D:$D,MATCH($H$4&"",'All Data'!$A:$A,0)),"-") | D6: WC MUorC % Total | E6: ==IFERROR(INDEX('All Data'!$J:$J,MATCH($H$4&"",'All Data'!$A:$A,0)),"-") | F6: Total Units | G6: ==IFERROR(INDEX('All Data'!$R:$R,MATCH($H$4&"",'All Data'!$A:$A,0)),"-")
B7: Households | C7: ==IFERROR(INDEX('All Data'!$E:$E,MATCH($H$4&"",'All Data'!$A:$A,0)),"-") | D7: Metropolitan Center | E7: ==IFERROR(INDEX('All Data'!$K:$K,MATCH($H$4&"",'All Data'!$A:$A,0)),"-") | F7: Residential Acres | G7: ==IFERROR(INDEX('All Data'!$S:$S,MATCH($H$4&"",'All Data'!$A:$A,0)),"-")
B8: Total Acres | C8: ==IFERROR(INDEX('All Data'!$F:$F,MATCH($H$4&"",'All Data'!$A:$A,0)),"-") | D8: Urban Center | E8: ==IFERROR(INDEX('All Data'!$L:$L,MATCH($H$4&"",'All Data'!$A:$A,0)),"-") | F8: SFD Acres | G8: ==IFERROR(INDEX('All Data'!$T:$T,MATCH($H$4&"",'All Data'!$A:$A,0)),"-")
B9: Developable Acres | C9: ==IFERROR(INDEX('All Data'!$G:$G,MATCH($H$4&"",'All Data'!$A:$A,0)),"-") | D9: City Center | E9: ==IFERROR(INDEX('All Data'!$M:$M,MATCH($H$4&"",'All Data'!$A:$A,0)),"-") | F9: MF / SFA Acres | G9: ==IFERROR(INDEX('All Data'!$U:$U,MATCH($H$4&"",'All Data'!$A:$A,0)),"-")
B10: OZ 1.0 Acres | C10: ==IFERROR(INDEX('All Data'!$H:$H,MATCH($H$4&"",'All Data'!$A:$A,0)),"-") | D10: Neighborhood Center | E10: ==IFERROR(INDEX('All Data'!$N:$N,MATCH($H$4&"",'All Data'!$A:$A,0)),"-") | F10: Poverty Rate | G10: ==IFERROR(INDEX('All Data'!$AL:$AL,MATCH($H$4&"",'All Data'!$A:$A,0)),"-")
B11: OZ 1.0 % of Tract | C11: ==IFERROR(INDEX('All Data'!$I:$I,MATCH($H$4&"",'All Data'!$A:$A,0)),"-") | D11: Employment District | E11: ==IFERROR(INDEX('All Data'!$O:$O,MATCH($H$4&"",'All Data'!$A:$A,0)),"-") | F11: Unemployment Rate | G11: ==IFERROR(INDEX('All Data'!$AM:$AM,MATCH($H$4&"",'All Data'!$A:$A,0)),"-")
D12: Industrial District | E12: ==IFERROR(INDEX('All Data'!$P:$P,MATCH($H$4&"",'All Data'!$A:$A,0)),"-") | F12: Median Family Income | G12: ==IFERROR(INDEX('All Data'!$AN:$AN,MATCH($H$4&"",'All Data'!$A:$A,0)),"-")
D13: Retail District | E13: ==IFERROR(INDEX('All Data'!$Q:$Q,MATCH($H$4&"",'All Data'!$A:$A,0)),"-")
B14: TRANSIT ACCESS | D14: AUTO ACCESS | F14: PROJECTED GROWTH 2027-37
B15: Rail / BRT Stops | C15: ==IFERROR(INDEX('All Data'!$V:$V,MATCH($H$4&"",'All Data'!$A:$A,0)),"-") | D15: Freeway Exits | E15: ==IFERROR(INDEX('All Data'!$AB:$AB,MATCH($H$4&"",'All Data'!$A:$A,0)),"-") | F15: Households Added | G15: ==IFERROR(INDEX('All Data'!$AG:$AG,MATCH($H$4&"",'All Data'!$A:$A,0)),"-")
B16: SAP Acres | C16: ==IFERROR(INDEX('All Data'!$W:$W,MATCH($H$4&"",'All Data'!$A:$A,0)),"-") | D16: Exit Distance (mi) | E16: ==IFERROR(INDEX('All Data'!$AC:$AC,MATCH($H$4&"",'All Data'!$A:$A,0)),"-") | F16: Population Added | G16: ==IFERROR(INDEX('All Data'!$AH:$AH,MATCH($H$4&"",'All Data'!$A:$A,0)),"-")
B17: SAP % of Tract | C17: ==IFERROR(INDEX('All Data'!$X:$X,MATCH($H$4&"",'All Data'!$A:$A,0)),"-") | D17: ATO Jobs (Auto) | E17: ==IFERROR(INDEX('All Data'!$AD:$AD,MATCH($H$4&"",'All Data'!$A:$A,0)),"-") | F17: Jobs Added | G17: ==IFERROR(INDEX('All Data'!$AI:$AI,MATCH($H$4&"",'All Data'!$A:$A,0)),"-")
B18: ATO Jobs (Transit) | C18: ==IFERROR(INDEX('All Data'!$Y:$Y,MATCH($H$4&"",'All Data'!$A:$A,0)),"-") | D18: ATO Households (Auto) | E18: ==IFERROR(INDEX('All Data'!$AE:$AE,MATCH($H$4&"",'All Data'!$A:$A,0)),"-") | F18: ERU Added | G18: ==IFERROR(INDEX('All Data'!$AJ:$AJ,MATCH($H$4&"",'All Data'!$A:$A,0)),"-")
B19: ATO Households (Transit) | C19: ==IFERROR(INDEX('All Data'!$Z:$Z,MATCH($H$4&"",'All Data'!$A:$A,0)),"-") | F19: ERU per Acre | G19: ==IFERROR(INDEX('All Data'!$AK:$AK,MATCH($H$4&"",'All Data'!$A:$A,0)),"-")
B20: SAP Planned HH/ac | C20: ==IFERROR(INDEX('All Data'!$AA:$AA,MATCH($H$4&"",'All Data'!$A:$A,0)),"-")
B22: INCOME | D22: POVERTY RATE | F22: UNEMPLOYMENT
C23: ==IFERROR(INDEX('All Data'!$AN:$AN,MATCH($H$4&"",'All Data'!$A:$A,0)),"-") | E23: ==IFERROR(INDEX('All Data'!$AL:$AL,MATCH($H$4&"",'All Data'!$A:$A,0)),"-") | G23: ==IFERROR(INDEX('All Data'!$AM:$AM,MATCH($H$4&"",'All Data'!$A:$A,0)),"-")
B24: =="Investment Likelihood: "&IFERROR(INDEX('All Data'!$AP:$AP,MATCH($H$4&"",'All Data'!$A:$A,0)),"—")
B25: Access to Opportunities (ATO) Composite Score /100 | F25: ==IFERROR(INDEX('All Data'!$AF:$AF,MATCH($H$4&"",'All Data'!$A:$A,0)),"-")
A29: =="02 — "&IFERROR(INDEX('All Data'!$C:$C,MATCH($H$29&"",'All Data'!$A:$A,0)),"")&" | GEOID "&$H$29&" | "&TEXT(IFERROR(INDEX('All Data'!$F:$F,MATCH($H$29&"",'All Data'!$A:$A,0)),0),"0")&" ac | "&IFERROR(INDEX('All Data'!$AP:$AP,MATCH($H$29&"",'All Data'!$A:$A,0)),"—") | H29: 49057200302
B30: TRACT PROFILE | D30: CENTERS & DISTRICTS | F30: HOUSING & DEMOGRAPHICS
B31: Population | C31: ==IFERROR(INDEX('All Data'!$D:$D,MATCH($H$29&"",'All Data'!$A:$A,0)),"-") | D31: WC MUorC % Total | E31: ==IFERROR(INDEX('All Data'!$J:$J,MATCH($H$29&"",'All Data'!$A:$A,0)),"-") | F31: Total Units | G31: ==IFERROR(INDEX('All Data'!$R:$R,MATCH($H$29&"",'All Data'!$A:$A,0)),"-")
B32: Households | C32: ==IFERROR(INDEX('All Data'!$E:$E,MATCH($H$29&"",'All Data'!$A:$A,0)),"-") | D32: Metropolitan Center | E32: ==IFERROR(INDEX('All Data'!$K:$K,MATCH($H$29&"",'All Data'!$A:$A,0)),"-") | F32: Residential Acres | G32: ==IFERROR(INDEX('All Data'!$S:$S,MATCH($H$29&"",'All Data'!$A:$A,0)),"-")
B33: Total Acres | C33: ==IFERROR(INDEX('All Data'!$F:$F,MATCH($H$29&"",'All Data'!$A:$A,0)),"-") | D33: Urban Center | E33: ==IFERROR(INDEX('All Data'!$L:$L,MATCH($H$29&"",'All Data'!$A:$A,0)),"-") | F33: SFD Acres | G33: ==IFERROR(INDEX('All Data'!$T:$T,MATCH($H$29&"",'All Data'!$A:$A,0)),"-")
B34: Developable Acres | C34: ==IFERROR(INDEX('All Data'!$G:$G,MATCH($H$29&"",'All Data'!$A:$A,0)),"-") | D34: City Center | E34: ==IFERROR(INDEX('All Data'!$M:$M,MATCH($H$29&"",'All Data'!$A:$A,0)),"-") | F34: MF / SFA Acres | G34: ==IFERROR(INDEX('All Data'!$U:$U,MATCH($H$29&"",'All Data'!$A:$A,0)),"-")
B35: OZ 1.0 Acres | C35: ==IFERROR(INDEX('All Data'!$H:$H,MATCH($H$29&"",'All Data'!$A:$A,0)),"-") | D35: Neighborhood Center | E35: ==IFERROR(INDEX('All Data'!$N:$N,MATCH($H$29&"",'All Data'!$A:$A,0)),"-") | F35: Poverty Rate | G35: ==IFERROR(INDEX('All Data'!$AL:$AL,MATCH($H$29&"",'All Data'!$A:$A,0)),"-")
B36: OZ 1.0 % of Tract | C36: ==IFERROR(INDEX('All Data'!$I:$I,MATCH($H$29&"",'All Data'!$A:$A,0)),"-") | D36: Employment District | E36: ==IFERROR(INDEX('All Data'!$O:$O,MATCH($H$29&"",'All Data'!$A:$A,0)),"-") | F36: Unemployment Rate | G36: ==IFERROR(INDEX('All Data'!$AM:$AM,MATCH($H$29&"",'All Data'!$A:$A,0)),"-")
D37: Industrial District | E37: ==IFERROR(INDEX('All Data'!$P:$P,MATCH($H$29&"",'All Data'!$A:$A,0)),"-") | F37: Median Family Income | G37: ==IFERROR(INDEX('All Data'!$AN:$AN,MATCH($H$29&"",'All Data'!$A:$A,0)),"-")
D38: Retail District | E38: ==IFERROR(INDEX('All Data'!$Q:$Q,MATCH($H$29&"",'All Data'!$A:$A,0)),"-")
B39: TRANSIT ACCESS | D39: AUTO ACCESS | F39: PROJECTED GROWTH 2027-37
B40: Rail / BRT Stops | C40: ==IFERROR(INDEX('All Data'!$V:$V,MATCH($H$29&"",'All Data'!$A:$A,0)),"-") | D40: Freeway Exits | E40: ==IFERROR(INDEX('All Data'!$AB:$AB,MATCH($H$29&"",'All Data'!$A:$A,0)),"-") | F40: Households Added | G40: ==IFERROR(INDEX('All Data'!$AG:$AG,MATCH($H$29&"",'All Data'!$A:$A,0)),"-")
B41: SAP Acres | C41: ==IFERROR(INDEX('All Data'!$W:$W,MATCH($H$29&"",'All Data'!$A:$A,0)),"-") | D41: Exit Distance (mi) | E41: ==IFERROR(INDEX('All Data'!$AC:$AC,MATCH($H$29&"",'All Data'!$A:$A,0)),"-") | F41: Population Added | G41: ==IFERROR(INDEX('All Data'!$AH:$AH,MATCH($H$29&"",'All Data'!$A:$A,0)),"-")
B42: SAP % of Tract | C42: ==IFERROR(INDEX('All Data'!$X:$X,MATCH($H$29&"",'All Data'!$A:$A,0)),"-") | D42: ATO Jobs (Auto) | E42: ==IFERROR(INDEX('All Data'!$AD:$AD,MATCH($H$29&"",'All Data'!$A:$A,0)),"-") | F42: Jobs Added | G42: ==IFERROR(INDEX('All Data'!$AI:$AI,MATCH($H$29&"",'All Data'!$A:$A,0)),"-")
B43: ATO Jobs (Transit) | C43: ==IFERROR(INDEX('All Data'!$Y:$Y,MATCH($H$29&"",'All Data'!$A:$A,0)),"-") | D43: ATO Households (Auto) | E43: ==IFERROR(INDEX('All Data'!$AE:$AE,MATCH($H$29&"",'All Data'!$A:$A,0)),"-") | F43: ERU Added | G43: ==IFERROR(INDEX('All Data'!$AJ:$AJ,MATCH($H$29&"",'All Data'!$A:$A,0)),"-")
B44: ATO Households (Transit) | C44: ==IFERROR(INDEX('All Data'!$Z:$Z,MATCH($H$29&"",'All Data'!$A:$A,0)),"-") | F44: ERU per Acre | G44: ==IFERROR(INDEX('All Data'!$AK:$AK,MATCH($H$29&"",'All Data'!$A:$A,0)),"-")
B45: SAP Planned HH/ac | C45: ==IFERROR(INDEX('All Data'!$AA:$AA,MATCH($H$29&"",'All Data'!$A:$A,0)),"-")
...

Sheet Davis County
A1: Davis County — OZ 2.0 Candidate Tracts — Detail
A2: WFRC & MAG Region | Generated June 01, 2026
A4: =="01 — "&IFERROR(INDEX('All Data'!$C:$C,MATCH($H$4&"",'All Data'!$A:$A,0)),"")&" | GEOID "&$H$4&" | "&TEXT(IFERROR(INDEX('All Data'!$F:$F,MATCH($H$4&"",'All Data'!$A:$A,0)),0),"0")&" ac | "&IFERROR(INDEX('All Data'!$AP:$AP,MATCH($H$4&"",'All Data'!$A:$A,0)),"—") | H4: 49011125201
B5: TRACT PROFILE | D5: CENTERS & DISTRICTS | F5: HOUSING & DEMOGRAPHICS
B6: Population | C6: ==IFERROR(INDEX('All Data'!$D:$D,MATCH($H$4&"",'All Data'!$A:$A,0)),"-") | D6: WC MUorC % Total | E6: ==IFERROR(INDEX('All Data'!$J:$J,MATCH($H$4&"",'All Data'!$A:$A,0)),"-") | F6: Total Units | G6: ==IFERROR(INDEX('All Data'!$R:$R,MATCH($H$4&"",'All Data'!$A:$A,0)),"-")
B7: Households | C7: ==IFERROR(INDEX('All Data'!$E:$E,MATCH($H$4&"",'All Data'!$A:$A,0)),"-") | D7: Metropolitan Center | E7: ==IFERROR(INDEX('All Data'!$K:$K,MATCH($H$4&"",'All Data'!$A:$A,0)),"-") | F7: Residential Acres | G7: ==IFERROR(INDEX('All Data'!$S:$S,MATCH($H$4&"",'All Data'!$A:$A,0)),"-")
B8: Total Acres | C8: ==IFERROR(INDEX('All Data'!$F:$F,MATCH($H$4&"",'All Data'!$A:$A,0)),"-") | D8: Urban Center | E8: ==IFERROR(INDEX('All Data'!$L:$L,MATCH($H$4&"",'All Data'!$A:$A,0)),"-") | F8: SFD Acres | G8: ==IFERROR(INDEX('All Data'!$T:$T,MATCH($H$4&"",'All Data'!$A:$A,0)),"-")
B9: Developable Acres | C9: ==IFERROR(INDEX('All Data'!$G:$G,MATCH($H$4&"",'All Data'!$A:$A,0)),"-") | D9: City Center | E9: ==IFERROR(INDEX('All Data'!$M:$M,MATCH($H$4&"",'All Data'!$A:$A,0)),"-") | F9: MF / SFA Acres | G9: ==IFERROR(INDEX('All Data'!$U:$U,MATCH($H$4&"",'All Data'!$A:$A,0)),"-")
B10: OZ 1.0 Acres | C10: ==IFERROR(INDEX('All Data'!$H:$H,MATCH($H$4&"",'All Data'!$A:$A,0)),"-") | D10: Neighborhood Center | E10: ==IFERROR(INDEX('All Data'!$N:$N,MATCH($H$4&"",'All Data'!$A:$A,0)),"-") | F10: Poverty Rate | G10: ==IFERROR(INDEX('All Data'!$AL:$AL,MATCH($H$4&"",'All Data'!$A:$A,0)),"-")
B11: OZ 1.0 % of Tract | C11: ==IFERROR(INDEX('All Data'!$I:$I,MATCH($H$4&"",'All Data'!$A:$A,0)),"-") | D11: Employment District | E11: ==IFERROR(INDEX('All Data'!$O:$O,MATCH($H$4&"",'All Data'!$A:$A,0)),"-") | F11: Unemployment Rate | G11: ==IFERROR(INDEX('All Data'!$AM:$AM,MATCH($H$4&"",'All Data'!$A:$A,0)),"-")
D12: Industrial District | E12: ==IFERROR(INDEX('All Data'!$P:$P,MATCH($H$4&"",'All Data'!$A:$A,0)),"-") | F12: Median Family Income | G12: ==IFERROR(INDEX('All Data'!$AN:$AN,MATCH($H$4&"",'All Data'!$A:$A,0)),"-")
D13: Retail District | E13: ==IFERROR(INDEX('All Data'!$Q:$Q,MATCH($H$4&"",'All Data'!$A:$A,0)),"-")
B14: TRANSIT ACCESS | D14: AUTO ACCESS | F14: PROJECTED GROWTH 2027-37
B15: Rail / BRT Stops | C15: ==IFERROR(INDEX('All Data'!$V:$V,MATCH($H$4&"",'All Data'!$A:$A,0)),"-") | D15: Freeway Exits | E15: ==IFERROR(INDEX('All Data'!$AB:$AB,MATCH($H$4&"",'All Data'!$A:$A,0)),"-") | F15: Households Added | G15: ==IFERROR(INDEX('All Data'!$AG:$AG,MATCH($H$4&"",'All Data'!$A:$A,0)),"-")
B16: SAP Acres | C16: ==IFERROR(INDEX('All Data'!$W:$W,MATCH($H$4&"",'All Data'!$A:$A,0)),"-") | D16: Exit Distance (mi) | E16: ==IFERROR(INDEX('All Data'!$AC:$AC,MATCH($H$4&"",'All Data'!$A:$A,0)),"-") | F16: Population Added | G16: ==IFERROR(INDEX('All Data'!$AH:$AH,MATCH($H$4&"",'All Data'!$A:$A,0)),"-")
B17: SAP % of Tract | C17: ==IFERROR(INDEX('All Data'!$X:$X,MATCH($H$4&"",'All Data'!$A:$A,0)),"-") | D17: ATO Jobs (Auto) | E17: ==IFERROR(INDEX('All Data'!$AD:$AD,MATCH($H$4&"",'All Data'!$A:$A,0)),"-") | F17: Jobs Added | G17: ==IFERROR(INDEX('All Data'!$AI:$AI,MATCH($H$4&"",'All Data'!$A:$A,0)),"-")
B18: ATO Jobs (Transit) | C18: ==IFERROR(INDEX('All Data'!$Y:$Y,MATCH($H$4&"",'All Data'!$A:$A,0)),"-") | D18: ATO Households (Auto) | E18: ==IFERROR(INDEX('All Data'!$AE:$AE,MATCH($H$4&"",'All Data'!$A:$A,0)),"-") | F18: ERU Added | G18: ==IFERROR(INDEX('All Data'!$AJ:$AJ,MATCH($H$4&"",'All Data'!$A:$A,0)),"-")
B19: ATO Households (Transit) | C19: ==IFERROR(INDEX('All Data'!$Z:$Z,MATCH($H$4&"",'All Data'!$A:$A,0)),"-") | F19: ERU per Acre | G19: ==IFERROR(INDEX('All Data'!$AK:$AK,MATCH($H$4&"",'All Data'!$A:$A,0)),"-")
B20: SAP Planned HH/ac | C20: ==IFERROR(INDEX('All Data'!$AA:$AA,MATCH($H$4&"",'All Data'!$A:$A,0)),"-")
B22: INCOME | D22: POVERTY RATE | F22: UNEMPLOYMENT
C23: ==IFERROR(INDEX('All Data'!$AN:$AN,MATCH($H$4&"",'All Data'!$A:$A,0)),"-") | E23: ==IFERROR(INDEX('All Data'!$AL:$AL,MATCH($H$4&"",'All Data'!$A:$A,0)),"-") | G23: ==IFERROR(INDEX('All Data'!$AM:$AM,MATCH($H$4&"",'All Data'!$A:$A,0)),"-")
B24: =="Investment Likelihood: "&IFERROR(INDEX('All Data'!$AP:$AP,MATCH($H$4&"",'All Data'!$A:$A,0)),"—")
B25: Access to Opportunities (ATO) Composite Score /100 | F25: ==IFERROR(INDEX('All Data'!$AF:$AF,MATCH($H$4&"",'All Data'!$A:$A,0)),"-")
A29: =="02 — "&IFERROR(INDEX('All Data'!$C:$C,MATCH($H$29&"",'All Data'!$A:$A,0)),"")&" | GEOID "&$H$29&" | "&TEXT(IFERROR(INDEX('All Data'!$F:$F,MATCH($H$29&"",'All Data'!$A:$A,0)),0),"0")&" ac | "&IFERROR(INDEX('All Data'!$AP:$AP,MATCH($H$29&"",'All Data'!$A:$A,0)),"—") | H29: 49011125301
B30: TRACT PROFILE | D30: CENTERS & DISTRICTS | F30: HOUSING & DEMOGRAPHICS
B31: Population | C31: ==IFERROR(INDEX('All Data'!$D:$D,MATCH($H$29&"",'All Data'!$A:$A,0)),"-") | D31: WC MUorC % Total | E31: ==IFERROR(INDEX('All Data'!$J:$J,MATCH($H$29&"",'All Data'!$A:$A,0)),"-") | F31: Total Units | G31: ==IFERROR(INDEX('All Data'!$R:$R,MATCH($H$29&"",'All Data'!$A:$A,0)),"-")
B32: Households | C32: ==IFERROR(INDEX('All Data'!$E:$E,MATCH($H$29&"",'All Data'!$A:$A,0)),"-") | D32: Metropolitan Center | E32: ==IFERROR(INDEX('All Data'!$K:$K,MATCH($H$29&"",'All Data'!$A:$A,0)),"-") | F32: Residential Acres | G32: ==IFERROR(INDEX('All Data'!$S:$S,MATCH($H$29&"",'All Data'!$A:$A,0)),"-")
B33: Total Acres | C33: ==IFERROR(INDEX('All Data'!$F:$F,MATCH($H$29&"",'All Data'!$A:$A,0)),"-") | D33: Urban Center | E33: ==IFERROR(INDEX('All Data'!$L:$L,MATCH($H$29&"",'All Data'!$A:$A,0)),"-") | F33: SFD Acres | G33: ==IFERROR(INDEX('All Data'!$T:$T,MATCH($H$29&"",'All Data'!$A:$A,0)),"-")
B34: Developable Acres | C34: ==IFERROR(INDEX('All Data'!$G:$G,MATCH($H$29&"",'All Data'!$A:$A,0)),"-") | D34: City Center | E34: ==IFERROR(INDEX('All Data'!$M:$M,MATCH($H$29&"",'All Data'!$A:$A,0)),"-") | F34: MF / SFA Acres | G34: ==IFERROR(INDEX('All Data'!$U:$U,MATCH($H$29&"",'All Data'!$A:$A,0)),"-")
B35: OZ 1.0 Acres | C35: ==IFERROR(INDEX('All Data'!$H:$H,MATCH($H$29&"",'All Data'!$A:$A,0)),"-") | D35: Neighborhood Center | E35: ==IFERROR(INDEX('All Data'!$N:$N,MATCH($H$29&"",'All Data'!$A:$A,0)),"-") | F35: Poverty Rate | G35: ==IFERROR(INDEX('All Data'!$AL:$AL,MATCH($H$29&"",'All Data'!$A:$A,0)),"-")
B36: OZ 1.0 % of Tract | C36: ==IFERROR(INDEX('All Data'!$I:$I,MATCH($H$29&"",'All Data'!$A:$A,0)),"-") | D36: Employment District | E36: ==IFERROR(INDEX('All Data'!$O:$O,MATCH($H$29&"",'All Data'!$A:$A,0)),"-") | F36: Unemployment Rate | G36: ==IFERROR(INDEX('All Data'!$AM:$AM,MATCH($H$29&"",'All Data'!$A:$A,0)),"-")
D37: Industrial District | E37: ==IFERROR(INDEX('All Data'!$P:$P,MATCH($H$29&"",'All Data'!$A:$A,0)),"-") | F37: Median Family Income | G37: ==IFERROR(INDEX('All Data'!$AN:$AN,MATCH($H$29&"",'All Data'!$A:$A,0)),"-")
D38: Retail District | E38: ==IFERROR(INDEX('All Data'!$Q:$Q,MATCH($H$29&"",'All Data'!$A:$A,0)),"-")
B39: TRANSIT ACCESS | D39: AUTO ACCESS | F39: PROJECTED GROWTH 2027-37
B40: Rail / BRT Stops | C40: ==IFERROR(INDEX('All Data'!$V:$V,MATCH($H$29&"",'All Data'!$A:$A,0)),"-") | D40: Freeway Exits | E40: ==IFERROR(INDEX('All Data'!$AB:$AB,MATCH($H$29&"",'All Data'!$A:$A,0)),"-") | F40: Households Added | G40: ==IFERROR(INDEX('All Data'!$AG:$AG,MATCH($H$29&"",'All Data'!$A:$A,0)),"-")
B41: SAP Acres | C41: ==IFERROR(INDEX('All Data'!$W:$W,MATCH($H$29&"",'All Data'!$A:$A,0)),"-") | D41: Exit Distance (mi) | E41: ==IFERROR(INDEX('All Data'!$AC:$AC,MATCH($H$29&"",'All Data'!$A:$A,0)),"-") | F41: Population Added | G41: ==IFERROR(INDEX('All Data'!$AH:$AH,MATCH($H$29&"",'All Data'!$A:$A,0)),"-")
B42: SAP % of Tract | C42: ==IFERROR(INDEX('All Data'!$X:$X,MATCH($H$29&"",'All Data'!$A:$A,0)),"-") | D42: ATO Jobs (Auto) | E42: ==IFERROR(INDEX('All Data'!$AD:$AD,MATCH($H$29&"",'All Data'!$A:$A,0)),"-") | F42: Jobs Added | G42: ==IFERROR(INDEX('All Data'!$AI:$AI,MATCH($H$29&"",'All Data'!$A:$A,0)),"-")
B43: ATO Jobs (Transit) | C43: ==IFERROR(INDEX('All Data'!$Y:$Y,MATCH($H$29&"",'All Data'!$A:$A,0)),"-") | D43: ATO Households (Auto) | E43: ==IFERROR(INDEX('All Data'!$AE:$AE,MATCH($H$29&"",'All Data'!$A:$A,0)),"-") | F43: ERU Added | G43: ==IFERROR(INDEX('All Data'!$AJ:$AJ,MATCH($H$29&"",'All Data'!$A:$A,0)),"-")
B44: ATO Households (Transit) | C44: ==IFERROR(INDEX('All Data'!$Z:$Z,MATCH($H$29&"",'All Data'!$A:$A,0)),"-") | F44: ERU per Acre | G44: ==IFERROR(INDEX('All Data'!$AK:$AK,MATCH($H$29&"",'All Data'!$A:$A,0)),"-")
B45: SAP Planned HH/ac | C45: ==IFERROR(INDEX('All Data'!$AA:$AA,MATCH($H$29&"",'All Data'!$A:$A,0)),"-")
...

Sheet Salt Lake County
A1: Salt Lake County — OZ 2.0 Candidate Tracts — Detail
A2: WFRC & MAG Region | Generated June 01, 2026
A4: =="01 — "&IFERROR(INDEX('All Data'!$C:$C,MATCH($H$4&"",'All Data'!$A:$A,0)),"")&" | GEOID "&$H$4&" | "&TEXT(IFERROR(INDEX('All Data'!$F:$F,MATCH($H$4&"",'All Data'!$A:$A,0)),0),"0")&" ac | "&IFERROR(INDEX('All Data'!$AP:$AP,MATCH($H$4&"",'All Data'!$A:$A,0)),"—") | H4: 49035100306
